<?xml version="1.0" encoding="UTF-8"?>
<!-- Generated by org.testng.reporters.JUnitReportReporter -->
<testsuite hostname="DESKTOP-8IFN1D6" failures="3" tests="3" name="Testcase.AsserionExample" time="0.022" errors="0" timestamp="07 Feb 2020 12:30:47 GMT" skipped="0">
  <testcase classname="Testcase.AsserionExample" name="Fail" time="0.004">
    <failure message="Failing the Test case" type="java.lang.AssertionError">
      <![CDATA[java.lang.AssertionError: Failing the Test case
at org.testng.Assert.fail(Assert.java:96)
at Testcase.AsserionExample.Fail(AsserionExample.java:26)
at java.base/jdk.internal.reflect.NativeMethodAccessorImpl.invoke0(Native Method)
at java.base/jdk.internal.reflect.NativeMethodAccessorImpl.invoke(NativeMethodAccessorImpl.java:62)
at java.base/jdk.internal.reflect.DelegatingMethodAccessorImpl.invoke(DelegatingMethodAccessorImpl.java:43)
at java.base/java.lang.reflect.Method.invoke(Method.java:567)
at org.testng.internal.MethodInvocationHelper.invokeMethod(MethodInvocationHelper.java:124)
at org.testng.internal.Invoker.invokeMethod(Invoker.java:583)
at org.testng.internal.Invoker.invokeTestMethod(Invoker.java:719)
at org.testng.internal.Invoker.invokeTestMethods(Invoker.java:989)
at org.testng.internal.TestMethodWorker.invokeTestMethods(TestMethodWorker.java:125)
at org.testng.internal.TestMethodWorker.run(TestMethodWorker.java:109)
at org.testng.TestRunner.privateRun(TestRunner.java:648)
at org.testng.TestRunner.run(TestRunner.java:505)
at org.testng.SuiteRunner.runTest(SuiteRunner.java:455)
at org.testng.SuiteRunner.runSequentially(SuiteRunner.java:450)
at org.testng.SuiteRunner.privateRun(SuiteRunner.java:415)
at org.testng.SuiteRunner.run(SuiteRunner.java:364)
at org.testng.SuiteRunnerWorker.runSuite(SuiteRunnerWorker.java:52)
at org.testng.SuiteRunnerWorker.run(SuiteRunnerWorker.java:84)
at org.testng.TestNG.runSuitesSequentially(TestNG.java:1208)
at org.testng.TestNG.runSuitesLocally(TestNG.java:1137)
at org.testng.TestNG.runSuites(TestNG.java:1049)
at org.testng.TestNG.run(TestNG.java:1017)
at org.testng.remote.AbstractRemoteTestNG.run(AbstractRemoteTestNG.java:115)
at org.testng.remote.RemoteTestNG.initAndRun(RemoteTestNG.java:251)
at org.testng.remote.RemoteTestNG.main(RemoteTestNG.java:77)
]]>
    </failure>
  </testcase> <!-- Fail -->
  <testcase classname="Testcase.AsserionExample" name="fail" time="0.004">
    <failure message="Testcase is failed expected [true] but found [false]" type="java.lang.AssertionError">
      <![CDATA[java.lang.AssertionError: Testcase is failed expected [true] but found [false]
at org.testng.Assert.fail(Assert.java:96)
at org.testng.Assert.failNotEquals(Assert.java:776)
at org.testng.Assert.assertTrue(Assert.java:44)
at Testcase.AsserionExample.fail(AsserionExample.java:22)
at java.base/jdk.internal.reflect.NativeMethodAccessorImpl.invoke0(Native Method)
at java.base/jdk.internal.reflect.NativeMethodAccessorImpl.invoke(NativeMethodAccessorImpl.java:62)
at java.base/jdk.internal.reflect.DelegatingMethodAccessorImpl.invoke(DelegatingMethodAccessorImpl.java:43)
at java.base/java.lang.reflect.Method.invoke(Method.java:567)
at org.testng.internal.MethodInvocationHelper.invokeMethod(MethodInvocationHelper.java:124)
at org.testng.internal.Invoker.invokeMethod(Invoker.java:583)
at org.testng.internal.Invoker.invokeTestMethod(Invoker.java:719)
at org.testng.internal.Invoker.invokeTestMethods(Invoker.java:989)
at org.testng.internal.TestMethodWorker.invokeTestMethods(TestMethodWorker.java:125)
at org.testng.internal.TestMethodWorker.run(TestMethodWorker.java:109)
at org.testng.TestRunner.privateRun(TestRunner.java:648)
at org.testng.TestRunner.run(TestRunner.java:505)
at org.testng.SuiteRunner.runTest(SuiteRunner.java:455)
at org.testng.SuiteRunner.runSequentially(SuiteRunner.java:450)
at org.testng.SuiteRunner.privateRun(SuiteRunner.java:415)
at org.testng.SuiteRunner.run(SuiteRunner.java:364)
at org.testng.SuiteRunnerWorker.runSuite(SuiteRunnerWorker.java:52)
at org.testng.SuiteRunnerWorker.run(SuiteRunnerWorker.java:84)
at org.testng.TestNG.runSuitesSequentially(TestNG.java:1208)
at org.testng.TestNG.runSuitesLocally(TestNG.java:1137)
at org.testng.TestNG.runSuites(TestNG.java:1049)
at org.testng.TestNG.run(TestNG.java:1017)
at org.testng.remote.AbstractRemoteTestNG.run(AbstractRemoteTestNG.java:115)
at org.testng.remote.RemoteTestNG.initAndRun(RemoteTestNG.java:251)
at org.testng.remote.RemoteTestNG.main(RemoteTestNG.java:77)
]]>
    </failure>
  </testcase> <!-- fail -->
  <testcase classname="Testcase.AsserionExample" name="validateTitles" time="0.014">
    <failure message="The following asserts failed:
	expected [yahoo.com] but found [gmail.com],
	Text box not present expected [true] but found [false],
	Test fail expected [true] but found [false]" type="java.lang.AssertionError">
      <![CDATA[java.lang.AssertionError: The following asserts failed:
expected [yahoo.com] but found [gmail.com],
Text box not present expected [true] but found [false],
Test fail expected [true] but found [false]
at org.testng.asserts.SoftAssert.assertAll(SoftAssert.java:43)
at Testcase.AsserionExample.validateTitles(AsserionExample.java:17)
at java.base/jdk.internal.reflect.NativeMethodAccessorImpl.invoke0(Native Method)
at java.base/jdk.internal.reflect.NativeMethodAccessorImpl.invoke(NativeMethodAccessorImpl.java:62)
at java.base/jdk.internal.reflect.DelegatingMethodAccessorImpl.invoke(DelegatingMethodAccessorImpl.java:43)
at java.base/java.lang.reflect.Method.invoke(Method.java:567)
at org.testng.internal.MethodInvocationHelper.invokeMethod(MethodInvocationHelper.java:124)
at org.testng.internal.Invoker.invokeMethod(Invoker.java:583)
at org.testng.internal.Invoker.invokeTestMethod(Invoker.java:719)
at org.testng.internal.Invoker.invokeTestMethods(Invoker.java:989)
at org.testng.internal.TestMethodWorker.invokeTestMethods(TestMethodWorker.java:125)
at org.testng.internal.TestMethodWorker.run(TestMethodWorker.java:109)
at org.testng.TestRunner.privateRun(TestRunner.java:648)
at org.testng.TestRunner.run(TestRunner.java:505)
at org.testng.SuiteRunner.runTest(SuiteRunner.java:455)
at org.testng.SuiteRunner.runSequentially(SuiteRunner.java:450)
at org.testng.SuiteRunner.privateRun(SuiteRunner.java:415)
at org.testng.SuiteRunner.run(SuiteRunner.java:364)
at org.testng.SuiteRunnerWorker.runSuite(SuiteRunnerWorker.java:52)
at org.testng.SuiteRunnerWorker.run(SuiteRunnerWorker.java:84)
at org.testng.TestNG.runSuitesSequentially(TestNG.java:1208)
at org.testng.TestNG.runSuitesLocally(TestNG.java:1137)
at org.testng.TestNG.runSuites(TestNG.java:1049)
at org.testng.TestNG.run(TestNG.java:1017)
at org.testng.remote.AbstractRemoteTestNG.run(AbstractRemoteTestNG.java:115)
at org.testng.remote.RemoteTestNG.initAndRun(RemoteTestNG.java:251)
at org.testng.remote.RemoteTestNG.main(RemoteTestNG.java:77)
]]>
    </failure>
  </testcase> <!-- validateTitles -->
</testsuite> <!-- Testcase.AsserionExample -->
